Workbook

Sheet FBT
A1: =[33]LAND!A1 -> TOMYPAK FLEXIBLE PACKAGING SDN BHD
A2: =[33]LAND!A2 -> FOR THE YEAR ENDED 30 JUNE 2025
A3: LEASEHOLD BUILDING (TAMPOI)
AA4: Closing | AB4: Opening
A5: Acquisition Date | B5: Disposal Date | C5: FA Description | D5: Cost c/f | E5: Addition | F5: Disposal/ Written off | G5: Cost b/f | I5: Years | J5: Acc Depn b/f | K5: Jul | L5: Aug | M5: Sept | N5: Oct | O5: Nov | P5: Dec | Q5: Jan | R5: Feb | S5: Mar | T5: Apr | U5: May | V5: Jun | W5: Current Year Depn | X5: Disposal/ Written off | Y5: Acc Depn c/f | AA5: NBV As At 30/06/2025 | AB5: NBV As At 30/06/2024
A6: 1988 | C6: Sykt Lian Mee-Electrical Installation | D6: 296000 | E6: 0 | F6: 0 | G6: =SUM(D6:F6) -> 296000 | I6: =40 -> 40 | J6: -218837.25 | K6: -616.67 | L6: -616.67 | M6: -616.67 | N6: -616.67 | O6: -616.67 | P6: -616.67 | Q6: -616.67 | R6: -616.67 | S6: -616.67 | T6: 0 | U6: 0 | V6: 0 | W6: =SUM(K6:V6) -> -5550.03 | X6: 0 | Y6: =J6+W6 -> -224387.28 | AA6: =G6+Y6 -> 71612.72 | AB6: =D6+J6 -> 77162.75
C7: Sykt Lian Mee-Additional work | D7: 647.35 | E7: 0 | F7: 0 | G7: =SUM(D7:F7) -> 647.35 | I7: 40 | J7: -479.03 | K7: -1.35 | L7: -1.35 | M7: -1.35 | N7: -1.35 | O7: -1.35 | P7: -1.35 | Q7: -1.35 | R7: -1.35 | S7: -1.35 | T7: 0 | U7: 0 | V7: 0 | W7: =SUM(K7:V7) -> -12.15 | X7: 0 | Y7: =J7+W7 -> -491.18 | AA7: =G7+Y7 -> 156.17 | AB7: =D7+J7 -> 168.32
C8: Flamex-Fire Fighting System | D8: 142500 | E8: 0 | F8: 0 | G8: =SUM(D8:F8) -> 142500 | I8: 40 | J8: -105353.43 | K8: -296.88 | L8: -296.88 | M8: -296.88 | N8: -296.88 | O8: -296.88 | P8: -296.88 | Q8: -296.88 | R8: -296.88 | S8: -296.88 | T8: 0 | U8: 0 | V8: 0 | W8: =SUM(K8:V8) -> -2671.92 | X8: 0 | Y8: =J8+W8 -> -108025.35 | AA8: =G8+Y8 -> 34474.65 | AB8: =D8+J8 -> 37146.57
C9: Sykt Lian Mee-Construction Cost | D9: 1471444.4 | E9: 0 | F9: 0 | G9: =SUM(D9:F9) -> 1471444.4 | I9: 40 | J9: -1087853.2 | K9: -3065.5 | L9: -3065.5 | M9: -3065.5 | N9: -3065.5 | O9: -3065.5 | P9: -3065.5 | Q9: -3065.5 | R9: -3065.5 | S9: -3065.5 | T9: 0 | U9: 0 | V9: 0 | W9: =SUM(K9:V9) -> -27589.5 | X9: 0 | Y9: =J9+W9 -> -1115442.7 | AA9: =G9+Y9 -> 356001.74 | AB9: =D9+J9 -> 383591.24
C10: Jurutera Lee-Professional Fee | D10: 14000 | E10: 0 | F10: 0 | G10: =SUM(D10:F10) -> 14000 | I10: 40 | J10: -10351.38 | K10: -29.17 | L10: -29.17 | M10: -29.17 | N10: -29.17 | O10: -29.17 | P10: -29.17 | Q10: -29.17 | R10: -29.17 | S10: -29.17 | T10: 0 | U10: 0 | V10: 0 | W10: =SUM(K10:V10) -> -262.53 | X10: 0 | Y10: =J10+W10 -> -10613.91 | AA10: =G10+Y10 -> 3386.09 | AB10: =D10+J10 -> 3648.62
C11: LLN-Electrical Supply | D11: 16787 | E11: 0 | F11: 0 | G11: =SUM(D11:F11) -> 16787 | I11: 40 | J11: -12409.95 | K11: -34.97 | L11: -34.97 | M11: -34.97 | N11: -34.97 | O11: -34.97 | P11: -34.97 | Q11: -34.97 | R11: -34.97 | S11: -34.97 | T11: 0 | U11: 0 | V11: 0 | W11: =SUM(K11:V11) -> -314.73 | X11: 0 | Y11: =J11+W11 -> -12724.68 | AA11: =G11+Y11 -> 4062.32 | AB11: =D11+J11 -> 4377.05
C12: Pembinaan CL Tan-Painting,Tiles,Concrete Work | D12: 4670 | E12: 0 | F12: 0 | G12: =SUM(D12:F12) -> 4670 | I12: 40 | J12: 0 | K12: 0 | L12: 0 | M12: 0 | N12: 0 | O12: 0 | P12: 0 | Q12: 0 | R12: 0 | S12: 0 | T12: 0 | U12: 0 | V12: 0 | W12: =SUM(K12:V12) -> 0 | X12: 0 | Y12: =J12+W12 -> 0 | AA12: =G12+Y12 -> 4670 | AB12: =D12+J12 -> 4670
C13: Sykt Lian Mee-Construction Cost | D13: 13184.65 | E13: 0 | F13: 0 | G13: =SUM(D13:F13) -> 13184.65 | I13: 40 | J13: -9748.19 | K13: -27.47 | L13: -27.47 | M13: -27.47 | N13: -27.47 | O13: -27.47 | P13: -27.47 | Q13: -27.47 | R13: -27.47 | S13: -27.47 | T13: 0 | U13: 0 | V13: 0 | W13: =SUM(K13:V13) -> -247.23 | X13: 0 | Y13: =J13+W13 -> -9995.42 | AA13: =G13+Y13 -> 3189.23 | AB13: =D13+J13 -> 3436.46
C14: Consultancy Fee For Fire Fighting System | D14: 1250 | E14: 0 | F14: 0 | G14: =SUM(D14:F14) -> 1250 | I14: 40 | J14: -922.86 | K14: -2.6 | L14: -2.6 | M14: -2.6 | N14: -2.6 | O14: -2.6 | P14: -2.6 | Q14: -2.6 | R14: -2.6 | S14: -2.6 | T14: 0 | U14: 0 | V14: 0 | W14: =SUM(K14:V14) -> -23.4 | X14: 0 | Y14: =J14+W14 -> -946.26 | AA14: =G14+Y14 -> 303.74 | AB14: =D14+J14 -> 327.14
C15: Additional Work At Building | D15: 37129.86 | E15: 0 | F15: 0 | G15: =SUM(D15:F15) -> 37129.86 | I15: 40 | J15: -27449.37 | K15: -77.35 | L15: -77.35 | M15: -77.35 | N15: -77.35 | O15: -77.35 | P15: -77.35 | Q15: -77.35 | R15: -77.35 | S15: -77.35 | T15: 0 | U15: 0 | V15: 0 | W15: =SUM(K15:V15) -> -696.15 | X15: 0 | Y15: =J15+W15 -> -28145.52 | AA15: =G15+Y15 -> 8984.34 | AB15: =D15+J15 -> 9680.49
D16: =SUM(D6:D15) -> 1997613.3 | E16: =SUM(E6:E15) -> 0 | F16: =SUM(F6:F15) -> 0 | G16: =SUM(G6:G15) -> 1997613.3 | J16: =SUM(J6:J15) -> -1473404.7 | K16: =SUM(K6:K15) -> -4151.96 | L16: =SUM(L6:L15) -> -4151.96 | M16: =SUM(M6:M15) -> -4151.96 | N16: =SUM(N6:N15) -> -4151.96 | O16: =SUM(O6:O15) -> -4151.96 | P16: =SUM(P6:P15) -> -4151.96 | Q16: =SUM(Q6:Q15) -> -4151.96 | ... Y16: =SUM(Y6:Y15) -> -1510772.3 | AA16: =SUM(AA6:AA15) -> 486841 | AB16: =SUM(AB6:AB15) -> 524208.64
A18: 1989 | C18: Ismail & Rakan2-Electrical Works 40% | D18: 7200 | E18: 0 | F18: 0 | G18: =SUM(D18:F18) -> 7200 | I18: 40 | J18: -5323.05 | K18: -15 | L18: -15 | M18: -15 | N18: -15 | O18: -15 | P18: -15 | Q18: -15 | R18: -15 | S18: -15 | T18: 0 | U18: 0 | V18: 0 | W18: =SUM(K18:V18) -> -135 | X18: 0 | Y18: =J18+W18 -> -5458.05 | AA18: =G18+Y18 -> 1741.95 | AB18: =D18+J18 -> 1876.95
C19: Sykt Lian Mee-Concrete Trench | D19: 4200 | E19: 0 | F19: 0 | G19: =SUM(D19:F19) -> 4200 | I19: 40 | J19: -3105.11 | K19: -8.75 | L19: -8.75 | M19: -8.75 | N19: -8.75 | O19: -8.75 | P19: -8.75 | Q19: -8.75 | R19: -8.75 | S19: -8.75 | T19: 0 | U19: 0 | V19: 0 | W19: =SUM(K19:V19) -> -78.75 | X19: 0 | Y19: =J19+W19 -> -3183.86 | AA19: =G19+Y19 -> 1016.14 | AB19: =D19+J19 -> 1094.89
D20: =SUM(D18:D19) -> 11400 | E20: =SUM(E18:E19) -> 0 | F20: =SUM(F18:F19) -> 0 | G20: =SUM(G18:G19) -> 11400 | J20: =SUM(J18:J19) -> -8428.16 | K20: =SUM(K18:K19) -> -23.75 | L20: =SUM(L18:L19) -> -23.75 | M20: =SUM(M18:M19) -> -23.75 | N20: =SUM(N18:N19) -> -23.75 | O20: =SUM(O18:O19) -> -23.75 | P20: =SUM(P18:P19) -> -23.75 | Q20: =SUM(Q18:Q19) -> -23.75 | ... Y20: =SUM(Y18:Y19) -> -8641.91 | AA20: =SUM(AA18:AA19) -> 2758.09 | AB20: =SUM(AB18:AB19) -> 2971.84
A22: 1990 | C22: Pembinaan CL Tan-Painting,Tiles,Concrete Work | D22: -4670 | E22: 0 | F22: 0 | G22: =SUM(D22:F22) -> -4670 | J22: 0 | K22: 0 | L22: 0 | M22: 0 | N22: 0 | O22: 0 | P22: 0 | Q22: 0 | R22: 0 | S22: 0 | T22: 0 | U22: 0 | V22: 0 | W22: =SUM(K22:V22) -> 0 | X22: 0 | Y22: =J22+W22 -> 0 | AA22: =G22+Y22 -> -4670 | AB22: =D22+J22 -> -4670
C23: Chun Seng-Contruction Work | D23: 40000 | E23: 0 | F23: 0 | G23: =SUM(D23:F23) -> 40000 | I23: 40 | J23: -29571.48 | K23: -83.33 | L23: -83.33 | M23: -83.33 | N23: -83.33 | O23: -83.33 | P23: -83.33 | Q23: -83.33 | R23: -83.33 | S23: -83.33 | T23: 0 | U23: 0 | V23: 0 | W23: =SUM(K23:V23) -> -749.97 | X23: 0 | Y23: =J23+W23 -> -30321.45 | AA23: =G23+Y23 -> 9678.55 | AB23: =D23+J23 -> 10428.52
C24: Timbalan Yg Dipertua-Extension Fty Application | D24: 220 | E24: 0 | F24: 0 | G24: =SUM(D24:F24) -> 220 | I24: 40 | J24: -163.14 | K24: -0.46 | L24: -0.46 | M24: -0.46 | N24: -0.46 | O24: -0.46 | P24: -0.46 | Q24: -0.46 | R24: -0.46 | S24: -0.46 | T24: 0 | U24: 0 | V24: 0 | W24: =SUM(K24:V24) -> -4.14 | X24: 0 | Y24: =J24+W24 -> -167.28 | AA24: =G24+Y24 -> 52.72 | AB24: =D24+J24 -> 56.86
C25: Audit Adjt-Revaluation Surplus | D25: 2190986.7 | E25: 0 | F25: 0 | G25: =SUM(D25:F25) -> 2190986.7 | I25: 40 | J25: -1619823.2 | K25: -4564.56 | L25: -4564.56 | M25: -4564.56 | N25: -4564.56 | O25: -4564.56 | P25: -4564.56 | Q25: -4564.56 | R25: -4564.56 | S25: -4564.56 | T25: 0 | U25: 0 | V25: 0 | W25: =SUM(K25:V25) -> -41081.04 | X25: 0 | Y25: =J25+W25 -> -1660904.2 | AA25: =G25+Y25 -> 530082.48 | AB25: =D25+J25 -> 571163.52
C26: Audit Adjt-Overstated Of Revaluation Surplus | D26: -953373.55 | E26: 0 | F26: 0 | G26: =SUM(D26:F26) -> -953373.55 | I26: 40 | J26: 704841.64 | K26: 1986.2 | L26: 1986.2 | M26: 1986.2 | N26: 1986.2 | O26: 1986.2 | P26: 1986.2 | Q26: 1986.2 | R26: 1986.2 | S26: 1986.2 | T26: 0 | U26: 0 | V26: 0 | W26: =SUM(K26:V26) -> 17875.8 | X26: 0 | Y26: =J26+W26 -> 722717.44 | AA26: =G26+Y26 -> -230656.11 | AB26: =D26+J26 -> -248531.91
C27: Audit Adjt-Revaluation Surplus Wrongly Charged | D27: -783956.45 | E27: 0 | F27: 0 | G27: =SUM(D27:F27) -> -783956.45 | I27: 40 | J27: 579587.32 | K27: 1633.24 | L27: 1633.24 | M27: 1633.24 | N27: 1633.24 | O27: 1633.24 | P27: 1633.24 | Q27: 1633.24 | R27: 1633.24 | S27: 1633.24 | T27: 0 | U27: 0 | V27: 0 | W27: =SUM(K27:V27) -> 14699.16 | X27: 0 | Y27: =J27+W27 -> 594286.48 | AA27: =G27+Y27 -> -189669.97 | AB27: =D27+J27 -> -204369.13
C28: Sykt Lian Mee-Repaid For Overprovided | D28: -117850.5 | E28: 0 | F28: 0 | G28: =SUM(D28:F28) -> -117850.5 | I28: 40 | J28: 87127.68 | K28: 245.52 | L28: 245.52 | M28: 245.52 | N28: 245.52 | O28: 245.52 | P28: 245.52 | Q28: 245.52 | R28: 245.52 | S28: 245.52 | T28: 0 | U28: 0 | V28: 0 | W28: =SUM(K28:V28) -> 2209.68 | X28: 0 | Y28: =J28+W28 -> 89337.36 | AA28: =G28+Y28 -> -28513.14 | AB28: =D28+J28 -> -30722.82
D29: =SUM(D22:D28) -> 371356.2 | E29: =SUM(E22:E28) -> 0 | F29: =SUM(F22:F28) -> 0 | G29: =SUM(G22:G28) -> 371356.2 | J29: =SUM(J22:J28) -> -278001.16 | K29: =SUM(K22:K28) -> -783.39 | L29: =SUM(L22:L28) -> -783.39 | M29: =SUM(M22:M28) -> -783.39 | N29: =SUM(N22:N28) -> -783.39 | O29: =SUM(O22:O28) -> -783.39 | P29: =SUM(P22:P28) -> -783.39 | Q29: =SUM(Q22:Q28) -> -783.39 | ... Y29: =SUM(Y22:Y28) -> -285051.67 | AA29: =SUM(AA22:AA28) -> 86304.53 | AB29: =SUM(AB22:AB28) -> 93355.04
A31: 1991 | C31: Sykt Lian Mee-2.5% Retention Sum On Extension | D31: 19640.49 | E31: 0 | F31: 0 | G31: =SUM(D31:F31) -> 19640.49 | I31: 40 | J31: -14522.76 | K31: -40.92 | L31: -40.92 | M31: -40.92 | N31: -40.92 | O31: -40.92 | P31: -40.92 | Q31: -40.92 | R31: -40.92 | S31: -40.92 | T31: 0 | U31: 0 | V31: 0 | W31: =SUM(K31:V31) -> -368.28 | X31: 0 | Y31: =J31+W31 -> -14891.04 | AA31: =G31+Y31 -> 4749.45 | AB31: =D31+J31 -> 5117.73
C32: Balance Of Contract Sum Of RM168,000 | D32: 7500 | E32: 0 | F32: 0 | G32: =SUM(D32:F32) -> 7500 | I32: 40 | J32: -5546.98 | K32: -15.63 | L32: -15.63 | M32: -15.63 | N32: -15.63 | O32: -15.63 | P32: -15.63 | Q32: -15.63 | R32: -15.63 | S32: -15.63 | T32: 0 | U32: 0 | V32: 0 | W32: =SUM(K32:V32) -> -140.67 | X32: 0 | Y32: =J32+W32 -> -5687.65 | AA32: =G32+Y32 -> 1812.35 | AB32: =D32+J32 -> 1953.02
C33: Extension Factory Building Fully Completed | D33: 765979.22 | E33: 0 | F33: 0 | G33: =SUM(D33:F33) -> 765979.22 | I33: 40 | J33: -566360.38 | K33: -1595.79 | L33: -1595.79 | M33: -1595.79 | N33: -1595.79 | O33: -1595.79 | P33: -1595.79 | Q33: -1595.79 | R33: -1595.79 | S33: -1595.79 | T33: 0 | U33: 0 | V33: 0 | W33: =SUM(K33:V33) -> -14362.11 | X33: 0 | Y33: =J33+W33 -> -580722.49 | AA33: =G33+Y33 -> 185256.73 | AB33: =D33+J33 -> 199618.84
C34: Sin Sin Construction-Progress Claim On Extension | D34: 52187 | E34: 0 | F34: 0 | G34: =SUM(D34:F34) -> 52187 | I34: 40 | J34: -38585.87 | K34: -108.72 | L34: -108.72 | M34: -108.72 | N34: -108.72 | O34: -108.72 | P34: -108.72 | Q34: -108.72 | R34: -108.72 | S34: -108.72 | T34: 0 | U34: 0 | V34: 0 | W34: =SUM(K34:V34) -> -978.48 | X34: 0 | Y34: =J34+W34 -> -39564.35 | AA34: =G34+Y34 -> 12622.65 | AB34: =D34+J34 -> 13601.13
D35: =SUM(D31:D34) -> 845306.71 | E35: =SUM(E31:E34) -> 0 | F35: =SUM(F31:F34) -> 0 | G35: =SUM(G31:G34) -> 845306.71 | J35: =SUM(J31:J34) -> -625015.99 | K35: =SUM(K31:K34) -> -1761.06 | L35: =SUM(L31:L34) -> -1761.06 | M35: =SUM(M31:M34) -> -1761.06 | N35: =SUM(N31:N34) -> -1761.06 | O35: =SUM(O31:O34) -> -1761.06 | P35: =SUM(P31:P34) -> -1761.06 | Q35: =SUM(Q31:Q34) -> -1761.06 | ... Y35: =SUM(Y31:Y34) -> -640865.53 | AA35: =SUM(AA31:AA34) -> 204441.18 | AB35: =SUM(AB31:AB34) -> 220290.72
A37: 1994 | C37: Revaluation Surplus | D37: 702649.14 | E37: 0 | F37: 0 | G37: =SUM(D37:F37) -> 702649.14 | I37: 40 | J37: -519666.87 | K37: -1463.85 | L37: -1463.85 | M37: -1463.85 | N37: -1463.85 | O37: -1463.85 | P37: -1463.85 | Q37: -1463.85 | R37: -1463.85 | S37: -1463.85 | T37: 0 | U37: 0 | V37: 0 | W37: =SUM(K37:V37) -> -13174.65 | X37: 0 | Y37: =J37+W37 -> -532841.52 | AA37: =G37+Y37 -> 169807.62 | AB37: =D37+J37 -> 182982.27
A39: 1995 | C39: Audit Adjustment On Revaluation Surplus | D39: -331600.59 | E39: 0 | F39: 0 | G39: =SUM(D39:F39) -> -331600.59 | J39: 244554.02 | K39: 690.83 | L39: 690.83 | M39: 690.83 | N39: 690.83 | O39: 690.83 | P39: 690.83 | Q39: 690.83 | R39: 690.83 | S39: 690.83 | T39: 0 | U39: 0 | V39: 0 | W39: =SUM(K39:V39) -> 6217.47 | X39: 0 | Y39: =J39+W39 -> 250771.49 | AA39: =G39+Y39 -> -80829.1 | AB39: =D39+J39 -> -87046.57
C40: Audit Adjt Of Accum Depn On Revaluation | D40: -331157.92 | E40: 0 | F40: 0 | G40: =SUM(D40:F40) -> -331157.92 | J40: 244228.26 | K40: 689.91 | L40: 689.91 | M40: 689.91 | N40: 689.91 | O40: 689.91 | P40: 689.91 | Q40: 689.91 | R40: 689.91 | S40: 689.91 | T40: 0 | U40: 0 | V40: 0 | W40: =SUM(K40:V40) -> 6209.19 | X40: 0 | Y40: =J40+W40 -> 250437.45 | AA40: =G40+Y40 -> -80720.47 | AB40: =D40+J40 -> -86929.66
C41: Jurutera Lee-Professional Fee | D41: 63171.68 | E41: 0 | F41: 0 | G41: =SUM(D41:F41) -> 63171.68 | J41: -46326.72 | K41: -131.61 | L41: -131.61 | M41: -131.61 | N41: -131.61 | O41: -131.61 | P41: -131.61 | Q41: -131.61 | R41: -131.61 | S41: -131.61 | T41: 0 | U41: 0 | V41: 0 | W41: =SUM(K41:V41) -> -1184.49 | X41: 0 | Y41: =J41+W41 -> -47511.21 | AA41: =G41+Y41 -> 15660.47 | AB41: =D41+J41 -> 16844.96
C42: Reclassify Of A/C For Installation & Renovations | D42: -289766.97 | E42: 0 | F42: 0 | G42: =SUM(D42:F42) -> -289766.97 | J42: 213702.76 | K42: 603.68 | L42: 603.68 | M42: 603.68 | N42: 603.68 | O42: 603.68 | P42: 603.68 | Q42: 603.68 | R42: 603.68 | S42: 603.68 | T42: 0 | U42: 0 | V42: 0 | W42: =SUM(K42:V42) -> 5433.12 | X42: 0 | Y42: =J42+W42 -> 219135.88 | AA42: =G42+Y42 -> -70631.09 | AB42: =D42+J42 -> -76064.21
C43: Eliminating Accum Depn of Inst & Ren reclassify | D43: 331600.59 | E43: 0 | F43: 0 | G43: =SUM(D43:F43) -> 331600.59 | J43: -244554.02 | K43: -690.83 | L43: -690.83 | M43: -690.83 | N43: -690.83 | O43: -690.83 | P43: -690.83 | Q43: -690.83 | R43: -690.83 | S43: -690.83 | T43: 0 | U43: 0 | V43: 0 | W43: =SUM(K43:V43) -> -6217.47 | X43: 0 | Y43: =J43+W43 -> -250771.49 | AA43: =G43+Y43 -> 80829.1 | AB43: =D43+J43 -> 87046.57
C44: Capitalise Of Work In Progress | D44: 3952116.6 | E44: 0 | F44: 0 | G44: =SUM(D44:F44) -> 3952116.6 | J44: -2898220 | K44: -8233.58 | L44: -8233.58 | M44: -8233.58 | N44: -8233.58 | O44: -8233.58 | P44: -8233.58 | Q44: -8233.58 | R44: -8233.58 | S44: -8233.58 | T44: 0 | U44: 0 | V44: 0 | W44: =SUM(K44:V44) -> -74102.22 | X44: 0 | Y44: =J44+W44 -> -2972322.3 | AA44: =G44+Y44 -> 979794.31 | AB44: =D44+J44 -> 1053896.5
C45: Capitalise Of Work In Progress | D45: 79580.15 | E45: 0 | F45: 0 | G45: =SUM(D45:F45) -> 79580.15 | J45: -58358.2 | K45: -165.79 | L45: -165.79 | M45: -165.79 | N45: -165.79 | O45: -165.79 | P45: -165.79 | Q45: -165.79 | R45: -165.79 | S45: -165.79 | T45: 0 | U45: 0 | V45: 0 | W45: =SUM(K45:V45) -> -1492.11 | X45: 0 | Y45: =J45+W45 -> -59850.31 | AA45: =G45+Y45 -> 19729.84 | AB45: =D45+J45 -> 21221.95
...

Sheet TR
A1: =[33]LAND!A1 -> TOMYPAK FLEXIBLE PACKAGING SDN BHD
A2: =[33]LAND!A2 -> FOR THE YEAR ENDED 30 JUNE 2025
A3: TAMPOI RETROFITTING
A4: 11101-024 | AI4: Closing | AK4: Closing | AL4: Opening
A5: Acquisition Date | B5: Disposal Date | C5: F/A Code | D5: F/A Description | E5: Suppliers | F5: Cost Ctr. 1 | G5: Cost Ctr. 2 | H5: Cost Ctr. 3 | I5: Purchase Order | J5: NO. | K5: Invoice No. | L5: Remarks | M5: Quantity | O5: Cost c/f | P5: Addition | Q5: Disposal/ Written off | R5: Cost b/f | S5: Months | T5: Acc Depn b/f | U5: Jul | V5: Aug | W5: Sept | X5: Oct | Y5: Nov | Z5: Dec | AA5: Jan | AB5: Feb | AC5: Mar | AD5: Apr | AE5: May | AF5: Jun | AG5: Current Year Depn | AH5: Disposal/ Written off | AI5: Acc Depn c/f | AK5: =FBT!AA5 -> NBV As At 30/06/2025 | AL5: =FBT!AB5 -> NBV As At 30/06/2024
A6: 45017 | C6: TR-23-A0100001 | D6: BLOCK A SUPPLY & INSTALL ROOFING FASCIA, CLADDING, HOARDING, ACMV & FIRE FIGHTING SERVICES, MACHINE ROOM, WALL PARTITION & CEILING WORK | E6: CBE M&E ENGINEERING SDN BHD | F6: TAMPOI | G6: MAINT | H6: GENERAL | I6: 2201137/ 2201483 | J6: PU46555/ DT1169/ DT1196/ DT1195/ DT1208/ DT1216/ DT1230/ DT1332 | K6: INV2502/ INV2520/ INV2542/ INV2547/ INV2560/ INV2577/ INV2590/ INV2643 | L6: Installaton | M6: 1 | N6: lot | O6: 3949300.1 | P6: 0 | Q6: 0 | R6: =SUM(O6:Q6) -> 3949300.1 | S6: 120 | T6: -493662.51 | U6: =-$R6/$S6 -> -32910.834 | V6: =-$R6/$S6 -> -32910.834 | W6: =-$R6/$S6 -> -32910.834 | X6: =-$R6/$S6 -> -32910.834 | Y6: =-$R6/$S6 -> -32910.834 | Z6: =-$R6/$S6 -> -32910.834 | AA6: =-$R6/$S6 -> -32910.834 | AB6: =-$R6/$S6 -> -32910.834 | AC6: =-$R6/$S6 -> -32910.834 | AD6: 0 | AE6: 0 | AF6: 0 | AG6: =SUM(U6:AF6) -> -296197.51 | AH6: 0 | AI6: =T6+AG6+AH6 -> -789860.02 | AK6: =R6+AI6 -> 3159440.1 | AL6: =O6+T6 -> 3455637.6 | AP6: ROOF, JACK ROOF, FASCIA, CLADDING & HORADING WORK BLOCK A FACTORY AREA
A7: 45292 | C7: TR-24-A0100002 | D7: SUPPLY & INSTALL RENOVATION WORK AT BLOCK B & BLOCK C (TAMPOI) | E7: CBE M&E ENGINEERING SDN BHD | F7: TAMPOI | G7: MAINT | H7: GENERAL | I7: 2300450 | J7: DT1262/ DT1333/ DT1340/ DT1351/ DT1373/ DT1374/ DT1387 | K7: INV2612/ INV2644/ INV2656/ INV2674/ INV2701/ INV2723/ INV2755 | L7: Installaton | M7: 1 | N7: lot | O7: 3273509 | P7: 0 | Q7: 0 | R7: =SUM(O7:Q7) -> 3273509 | S7: 120 | T7: -163675.45 | U7: =-$R7/$S7 -> -27279.242 | V7: =-$R7/$S7 -> -27279.242 | W7: =-$R7/$S7 -> -27279.242 | X7: =-$R7/$S7 -> -27279.242 | Y7: =-$R7/$S7 -> -27279.242 | Z7: =-$R7/$S7 -> -27279.242 | AA7: =-$R7/$S7 -> -27279.242 | AB7: =-$R7/$S7 -> -27279.242 | AC7: =-$R7/$S7 -> -27279.242 | AD7: 0 | AE7: 0 | AF7: 0 | AG7: =SUM(U7:AF7) -> -245513.17 | AH7: 0 | AI7: =T7+AG7+AH7 -> -409188.62 | AK7: =R7+AI7 -> 2864320.4 | AL7: =O7+T7 -> 3109833.5 | AS7: Date | AT7: % | AU7: Total | AV7: Paid | AW7: TPO
AP8: Original Contract Sum | AU8: 4000000 | AW8: 2201137
O9: =SUM(O6:O8) -> 7222809.1 | P9: =SUM(P6:P8) -> 0 | Q9: =SUM(Q6:Q8) -> 0 | R9: =SUM(R6:R8) -> 7222809.1 | T9: =SUM(T6:T8) -> -657337.96 | U9: =SUM(U6:U8) -> -60190.076 | V9: =SUM(V6:V8) -> -60190.076 | W9: =SUM(W6:W8) -> -60190.076 | X9: =SUM(X6:X8) -> -60190.076 | Y9: =SUM(Y6:Y8) -> -60190.076 | Z9: =SUM(Z6:Z8) -> -60190.076 | AA9: =SUM(AA6:AA8) -> -60190.076 | ... AI9: =SUM(AI6:AI8) -> -1199048.6 | AK9: =SUM(AK6:AK8) -> 6023760.5 | AL9: =SUM(AL6:AL8) -> 6565471.1 | AP9: Less: Billing | AW9: 2201483
AP10: 40% DOWN PAYMENT | AQ10: PU46555 | AR10: INV2502 | AS10: 44770 | AT10: =AU10/AU$8 -> 0.4 | AU10: 1600000 | AV10: 1600000
AG11: In Balance Sheet as at 31/3/25 | AI11: -1199048.6 | AP11: PROGRESS CLAIM #1 | AQ11: DT1169 | AR11: INV2520 | AS11: 44835 | AT11: =AU11/AU$8 -> 0.15112576 | AU11: 604503.02 | AV11: 604503.02
AP12: PROGRESS CLAIM #2 | AQ12: DT1196 | AR12: INV2542 | AS12: 44865 | AT12: =AU12/AU$8 -> 0.16466032 | AU12: 658641.26 | AV12: 658641.26
AP13: PROGRESS CLAIM #3 | AQ13: DT1195 | AR13: INV2547 | AS13: 44879 | AT13: =AU13/AU$8 -> 0.070295625 | AU13: 281182.5 | AV13: 281182.5
AP14: PROGRESS CLAIM #4 | AQ14: DT1208 | AR14: INV2560 | AS14: 44903 | AT14: =AU14/AU$8 -> 0.03806458 | AU14: 152258.32 | AV14: 152258.32
AP15: PROGRESS CLAIM #5 | AQ15: DT1216 | AR15: INV2577 | AS15: 44932 | AT15: =AU15/AU$8 -> 0.059450058 | AU15: 237800.23 | AV15: 237800.23
AP16: PROGRESS CLAIM #6 | AQ16: DT1230 | AR16: INV2590 | AS16: 44957 | AT16: =AU16/AU$8 -> 0.033525345 | AU16: 134101.38 | AV16: =46941+87160.38 -> 134101.38
AP17: PROGRESS CLAIM #7 | AQ17: DT1332 | AR17: INV2643 | AS17: 45084 | AT17: =AU17/AU$8 -> 0.070203235 | AU17: 280812.94 | AV17: 280812.94
AT18: =SUM(AT8:AT17) -> 0.98732491 | AU18: =SUM(AU10:AU17) -> 3949299.6
AU19: =SUM(AU8)-SUM(AU18) -> 50700.35 | AV19: =SUM(AV10:AV18) -> 3949299.6
AP21: Renovation Work at Block B & C
AS22: Date | AT22: % | AU22: Total | AV22: Paid | AW22: Due | AX22: TPO
AP23: Original Contract Sum | AU23: 3280000 | AX23: 2300450
AP24: Less: Billing
AP25: 40% DOWN PAYMENT | AQ25: DT1262 | AR25: INV2612 | AS25: 45007 | AT25: =AU25/AU$23 -> 0.4 | AU25: 1312000 | AV25: 1312000 | AW25: =AU25-AV25 -> 0
AP26: PROGRESS CLAIM #1 | AQ26: DT1333 | AR26: INV2644 | AS26: 45084 | AT26: =AU26/AU$23 -> 0.16587002 | AU26: 544053.67 | AV26: 544053.67 | AW26: =AU26-AV26 -> 0
AP27: PROGRESS CLAIM #2 | AQ27: DT1340 | AR27: INV2656 | AS27: 45111 | AT27: =AU27/AU$23 -> 0.12754377 | AU27: 418343.55 | AV27: 418343.55 | AW27: =AU27-AV27 -> 0
AP28: PROGRESS CLAIM #3 | AQ28: DT1351 | AR28: INV2674 | AS28: 45138 | AT28: =AU28/AU$23 -> 0.069764271 | AU28: 228826.81 | AV28: 228826.81 | AW28: =AU28-AV28 -> 0
AP29: PROGRESS CLAIM #4 | AQ29: DT1373 | AR29: INV2701 | AS29: 45170 | AT29: =AU29/AU$23 -> 0.075523854 | AU29: 247718.24 | AV29: =AU29 -> 247718.24 | AW29: =AU29-AV29 -> 0
AP30: PROGRESS CLAIM #5 | AQ30: DT1374 | AR30: INV2723 | AS30: 45199 | AT30: =AU30/AU$23 -> 0.08027471 | AU30: 263301.05 | AV30: =AU30 -> 263301.05 | AW30: =AU30-AV30 -> 0
AP31: PROGRESS CLAIM #6 | AQ31: DT1387 | AR31: INV2755 | AS31: 45245 | AT31: =AU31/AU$23 -> 0.045560826 | AU31: 149439.51 | AV31: =47000+10000+10000+30000+50000 -> 147000 | AW31: =AU31-AV31 -> 2439.51 | AX31: *Updated up to 31.12.2024
AP32: PROGRESS CLAIM #7 | AQ32: DT1436 | AR32: INV2888 | AS32: 45427 | AT32: =AU32/AU$23 -> 0.033483588 | AU32: 109826.17 | AV32: 0 | AW32: =AU32-AV32 -> 109826.17
AT33: =SUM(AT22:AT32) -> 0.99802104 | AU33: =SUM(AU25:AU32) -> 3273509
AU34: =SUM(AU23)-SUM(AU33) -> 6491 | AV34: =SUM(AV24:AV33) -> 3161243.3 | AW34: =SUM(AW24:AW33) -> 112265.68
F67: `

Sheet IR
A1: =[33]LAND!A1 -> TOMYPAK FLEXIBLE PACKAGING SDN BHD
A2: =[33]LAND!A2 -> FOR THE YEAR ENDED 30 JUNE 2025
A3: INSTALLATION AND RENOVATION
A4: 11101-013 | AI4: Closing | AK4: Closing | AL4: Opening
A5: Acquisition Date | B5: Disposal Date | C5: F/A Code | D5: F/A Description | E5: Suppliers | F5: Cost Ctr. 1 | G5: Cost Ctr. 2 | H5: Cost Ctr. 3 | I5: Purchase Order | J5: NO. | K5: Invoice No. | L5: Remarks | M5: Quantity | O5: Cost c/f | P5: Addition | Q5: Disposal/ Written off | R5: Cost b/f | S5: Months | T5: Acc Depn b/f | U5: Jul | V5: Aug | W5: Sept | X5: Oct | Y5: Nov | Z5: Dec | AA5: Jan | AB5: Feb | AC5: Mar | AD5: Apr | AE5: May | AF5: Jun | AG5: Current Year Depn | AH5: Disposal/ Written off | AI5: Acc Depn c/f | AK5: =FBT!AA5 -> NBV As At 30/06/2025 | AL5: =FBT!AB5 -> NBV As At 30/06/2024
A6: 40755 | C6: IR10-001/01 | D6: GLASS PARTITION AT NEW R&D OFFICE | F6: TAMPOI | G6: RND | H6: General | M6: 1 | N6: Unit | O6: 1900 | P6: 0 | Q6: 0 | R6: =SUM(O6:Q6) -> 1900 | S6: 300 | T6: -1107.82 | U6: -6.33 | V6: =-$R6/$S6 -> -6.3333333 | W6: =-$R6/$S6 -> -6.3333333 | X6: =-$R6/$S6 -> -6.3333333 | Y6: =-$R6/$S6 -> -6.3333333 | Z6: =-$R6/$S6 -> -6.3333333 | AA6: =-$R6/$S6 -> -6.3333333 | AB6: =-$R6/$S6 -> -6.3333333 | AC6: =-$R6/$S6 -> -6.3333333 | AD6: 0 | AE6: 0 | AF6: 0 | AG6: =SUM(U6:AF6) -> -56.996667 | AH6: 0 | AI6: =T6+AG6+AH6 -> -1164.8167 | AK6: =R6+AI6 -> 735.18333 | AL6: =O6+T6 -> 792.18
A7: 44782 | C7: IR-22-A0100090 | D7: WALLPAPER INSTALLATION AT BLOCK A MAIN OFFICE | E7: COB CARPET & RENOVATION SDN BHD | F7: TAMPOI | G7: HR | H7: GENERAL | I7: N/A | J7: PU46717 | K7: 20220086 | L7: Installation works | M7: 14 | N7: ROLL | O7: 6192.63 | P7: 0 | Q7: 0 | R7: =SUM(O7:Q7) -> 6192.63 | S7: 60 | T7: -2373.8345 | U7: -103.21 | V7: =-$R7/$S7 -> -103.2105 | W7: =-$R7/$S7 -> -103.2105 | X7: =-$R7/$S7 -> -103.2105 | Y7: =-$R7/$S7 -> -103.2105 | Z7: =-$R7/$S7 -> -103.2105 | AA7: =-$R7/$S7 -> -103.2105 | AB7: =-$R7/$S7 -> -103.2105 | AC7: =-$R7/$S7 -> -103.2105 | AD7: 0 | AE7: 0 | AF7: 0 | AG7: =SUM(U7:AF7) -> -928.894 | AH7: 0 | AI7: =T7+AG7+AH7 -> -3302.7285 | AK7: =R7+AI7 -> 2889.9015 | AL7: =O7+T7 -> 3818.7955
A8: 44782 | C8: IR-22-B0100090 | D8: DISMANTLE EXISTING WALLPAPER AT BLOCK A MAIN OFFICE | E8: COB CARPET & RENOVATION SDN BHD | F8: TAMPOI | G8: HR | H8: GENERAL | I8: N/A | J8: PU46717 | K8: 20220086 | L8: Installation works | M8: 1600 | N8: SQFT | O8: 1326.99 | P8: 0 | Q8: 0 | R8: =SUM(O8:Q8) -> 1326.99 | S8: 60 | T8: -508.7285 | U8: -22.12 | V8: =-$R8/$S8 -> -22.1165 | W8: =-$R8/$S8 -> -22.1165 | X8: =-$R8/$S8 -> -22.1165 | Y8: =-$R8/$S8 -> -22.1165 | Z8: =-$R8/$S8 -> -22.1165 | AA8: =-$R8/$S8 -> -22.1165 | AB8: =-$R8/$S8 -> -22.1165 | AC8: =-$R8/$S8 -> -22.1165 | AD8: 0 | AE8: 0 | AF8: 0 | AG8: =SUM(U8:AF8) -> -199.052 | AH8: 0 | AI8: =T8+AG8+AH8 -> -707.7805 | AK8: =R8+AI8 -> 619.2095 | AL8: =O8+T8 -> 818.2615
A9: 44782 | C9: IR-22-B0200090 | D9: PAINTING AT BLOCK A MAIN OFFICE | E9: COB CARPET & RENOVATION SDN BHD | F9: TAMPOI | G9: HR | H9: GENERAL | I9: N/A | J9: PU46717 | K9: 20220086 | L9: Installation works | M9: 1 | N9: JOB | O9: 230.38 | P9: 0 | Q9: 0 | R9: =SUM(O9:Q9) -> 230.38 | S9: 36 | T9: -147.195 | U9: -6.4 | V9: =-$R9/$S9 -> -6.3994444 | W9: =-$R9/$S9 -> -6.3994444 | X9: =-$R9/$S9 -> -6.3994444 | Y9: =-$R9/$S9 -> -6.3994444 | Z9: =-$R9/$S9 -> -6.3994444 | AA9: =-$R9/$S9 -> -6.3994444 | AB9: =-$R9/$S9 -> -6.3994444 | AC9: =-$R9/$S9 -> -6.3994444 | AD9: 0 | AE9: 0 | AF9: 0 | AG9: =SUM(U9:AF9) -> -57.595556 | AH9: 0 | AI9: =T9+AG9+AH9 -> -204.79056 | AK9: =R9+AI9 -> 25.589444 | AL9: =O9+T9 -> 83.185
A10: 41214 | C10: IR-00001A01-12 | D10: Extend 4ft For HR Office | F10: TAMPOI | G10: HR | H10: General | M10: 1 | N10: Unit | O10: 469 | P10: 0 | Q10: 0 | R10: =SUM(O10:Q10) -> 469 | S10: 120 | T10: -469 | U10: 0 | V10: 0 | W10: 0 | X10: 0 | Y10: 0 | Z10: 0 | AA10: 0 | AB10: 0 | AC10: 0 | AD10: 0 | AE10: 0 | AF10: 0 | AG10: =SUM(U10:AF10) -> 0 | AH10: 0 | AI10: =T10+AG10+AH10 -> -469 | AK10: =R10+AI10 -> 0 | AL10: =O10+T10 -> 0
A11: 44782 | C11: IR-22-B0100091 | D11: PAINTING JOB AT BLOCK A MAIN OFFICE | E11: FEI XIONG INTERIOR & RENOVATION | F11: TAMPOI | G11: HR | H11: GENERAL | I11: N/A | J11: PU46718 | K11: 0337 | L11: Installation works | M11: 1 | N11: JOB | O11: 4300 | P11: 0 | Q11: 0 | R11: =SUM(O11:Q11) -> 4300 | S11: 60 | T11: -1648.38 | U11: -71.67 | V11: =-$R11/$S11 -> -71.666667 | W11: =-$R11/$S11 -> -71.666667 | X11: =-$R11/$S11 -> -71.666667 | Y11: =-$R11/$S11 -> -71.666667 | Z11: =-$R11/$S11 -> -71.666667 | AA11: =-$R11/$S11 -> -71.666667 | AB11: =-$R11/$S11 -> -71.666667 | AC11: =-$R11/$S11 -> -71.666667 | AD11: 0 | AE11: 0 | AF11: 0 | AG11: =SUM(U11:AF11) -> -645.00333 | AH11: 0 | AI11: =T11+AG11+AH11 -> -2293.3833 | AK11: =R11+AI11 -> 2006.6167 | AL11: =O11+T11 -> 2651.62
A12: 41214 | C12: IR-00002A01-12 | D12: Purchasing Office | F12: TAMPOI | G12: HR | H12: General | M12: 1 | N12: Unit | O12: 3589 | P12: 0 | Q12: 0 | R12: =SUM(O12:Q12) -> 3589 | S12: 120 | T12: -3589 | U12: 0 | V12: 0 | W12: 0 | X12: 0 | Y12: 0 | Z12: 0 | AA12: 0 | AB12: 0 | AC12: 0 | AD12: 0 | AE12: 0 | AF12: 0 | AG12: =SUM(U12:AF12) -> 0 | AH12: 0 | AI12: =T12+AG12+AH12 -> -3589 | AK12: =R12+AI12 -> 0 | AL12: =O12+T12 -> 0
A13: 41214 | C13: IR-00003A01-12 | D13: Door & Window | F13: TAMPOI | G13: HR | H13: General | M13: 1 | N13: Unit | O13: 4196 | P13: 0 | Q13: 0 | R13: =SUM(O13:Q13) -> 4196 | S13: 120 | T13: -4196 | U13: 0 | V13: 0 | W13: 0 | X13: 0 | Y13: 0 | Z13: 0 | AA13: 0 | AB13: 0 | AC13: 0 | AD13: 0 | AE13: 0 | AF13: 0 | AG13: =SUM(U13:AF13) -> 0 | AH13: 0 | AI13: =T13+AG13+AH13 -> -4196 | AK13: =R13+AI13 -> 0 | AL13: =O13+T13 -> 0
A14: 44782 | C14: IR-22-B0200092 | D14: SERVICE INSTALLATION JOB AT BLOCK A MAIN OFFICE RENOVATION WORK AT TAMPOI MAIN OFFICE BLOCK A | E14: KK OFFICEPOINT SDN BHD | F14: TAMPOI | G14: HR | H14: GENERAL | I14: N/A | J14: PU46721 | K14: IN2206-0051 | L14: Installation works | M14: 1 | N14: JOB | O14: 200 | P14: 0 | Q14: 0 | R14: =SUM(O14:Q14) -> 200 | S14: 60 | T14: -76.62 | U14: -3.33 | V14: =-$R14/$S14 -> -3.3333333 | W14: =-$R14/$S14 -> -3.3333333 | X14: =-$R14/$S14 -> -3.3333333 | Y14: =-$R14/$S14 -> -3.3333333 | Z14: =-$R14/$S14 -> -3.3333333 | AA14: =-$R14/$S14 -> -3.3333333 | AB14: =-$R14/$S14 -> -3.3333333 | AC14: =-$R14/$S14 -> -3.3333333 | AD14: 0 | AE14: 0 | AF14: 0 | AG14: =SUM(U14:AF14) -> -29.996667 | AH14: 0 | AI14: =T14+AG14+AH14 -> -106.61667 | AK14: =R14+AI14 -> 93.383333 | AL14: =O14+T14 -> 123.38
A15: 42094 | C15: IR-00012A01-15 | D15: BRAND: CANSTAR CONE; MODEL: CCF58-31A | F15: TAMPOI | G15: CPP | H15: General | M15: 1 | N15: Unit | O15: 47000 | P15: 0 | Q15: 0 | R15: =SUM(O15:Q15) -> 47000 | S15: 120 | T15: -44258.68 | U15: -391.67 | V15: =-$R15/$S15 -> -391.66667 | W15: =-$R15/$S15 -> -391.66667 | X15: =-$R15/$S15 -> -391.66667 | Y15: =-$R15/$S15 -> -391.66667 | Z15: =-$R15/$S15 -> -391.66667 | AA15: =-$R15/$S15+0.35 -> -391.31667 | AB15: 0 | AC15: 0 | AD15: 0 | AE15: 0 | AF15: 0 | AG15: =SUM(U15:AF15) -> -2741.32 | AH15: 0 | AI15: =T15+AG15+AH15 -> -47000 | AK15: =R15+AI15 -> 0 | AL15: =O15+T15 -> 2741.32
A16: 44826 | C16: IR-22-A0100093 | D16: MATERIALS, LABOUR, EQUIPMENT AND CONSUMABLE TO FABRICATE AND INSTALL MACHINERY FOUNDATION | E16: F-I ENGINEERING SDN BHD | F16: TAMPOI | G16: MAINT | H16: GENERAL | I16: 2200932 | J16: DT 1023/ DT 1091/ DT 1164 | K16: 6780/ 6899/ 6921 | L16: Installation works | M16: 1 | N16: Unit | O16: 560000 | P16: 0 | Q16: 0 | R16: =SUM(O16:Q16) -> 560000 | S16: 120 | T16: -102666.71 | U16: -4666.67 | V16: =-$R16/$S16 -> -4666.6667 | W16: =-$R16/$S16 -> -4666.6667 | X16: =-$R16/$S16 -> -4666.6667 | Y16: =-$R16/$S16 -> -4666.6667 | Z16: =-$R16/$S16 -> -4666.6667 | AA16: =-$R16/$S16 -> -4666.6667 | AB16: =-$R16/$S16 -> -4666.6667 | AC16: =-$R16/$S16 -> -4666.6667 | AD16: 0 | AE16: 0 | AF16: 0 | AG16: =SUM(U16:AF16) -> -42000.003 | AH16: 0 | AI16: =T16+AG16+AH16 -> -144666.71 | AK16: =R16+AI16 -> 415333.29 | AL16: =O16+T16 -> 457333.29
A17: 44859 | C17: IR-22-A0100094 | D17: CONSTRUCT R.C PIT STRUCTURE, PROVIDE ALL FORMWORK, TIE ROD AND CAST 200MM THICK CONCRETE WITH BRC A8, T12 STARTER BAR 300 C/C ON EXISTING CONCRETE FLOOR | E17: F-I ENGINEERING SDN BHD | F17: TAMPOI | G17: MAINT | H17: GENERAL | I17: 2201338 | J17: DT 1122/ DT1170 | K17: 6907/ 6942 | L17: Installation works | M17: 1 | N17: Unit | O17: 43000 | P17: 0 | Q17: 0 | R17: =SUM(O17:Q17) -> 43000 | S17: 120 | T17: -7524.96 | U17: -358.33 | V17: =-$R17/$S17 -> -358.33333 | W17: =-$R17/$S17 -> -358.33333 | X17: =-$R17/$S17 -> -358.33333 | Y17: =-$R17/$S17 -> -358.33333 | Z17: =-$R17/$S17 -> -358.33333 | AA17: =-$R17/$S17 -> -358.33333 | AB17: =-$R17/$S17 -> -358.33333 | AC17: =-$R17/$S17 -> -358.33333 | AD17: 0 | AE17: 0 | AF17: 0 | AG17: =SUM(U17:AF17) -> -3224.9967 | AH17: 0 | AI17: =T17+AG17+AH17 -> -10749.957 | AK17: =R17+AI17 -> 32250.043 | AL17: =O17+T17 -> 35475.04
A18: 42124 | C18: IR-00013A01-15 | D18: GOLD AROWANA (30X60 INS) | F18: TAMPOI | G18: HR | H18: General | M18: 1 | N18: Unit | O18: 20888 | P18: 0 | Q18: 0 | R18: =SUM(O18:Q18) -> 20888 | S18: 120 | T18: -19495.81 | U18: -174.07 | V18: =-$R18/$S18 -> -174.06667 | W18: =-$R18/$S18 -> -174.06667 | X18: =-$R18/$S18 -> -174.06667 | Y18: =-$R18/$S18 -> -174.06667 | Z18: =-$R18/$S18 -> -174.06667 | AA18: =-$R18/$S18 -> -174.06667 | AB18: -173.72 | AC18: 0 | AD18: 0 | AE18: 0 | AF18: 0 | AG18: =SUM(U18:AF18) -> -1392.19 | AH18: 0 | AI18: =T18+AG18+AH18 -> -20888 | AK18: =R18+AI18 -> 0 | AL18: =O18+T18 -> 1392.19
A19: 43221 | C19: IR-00041A01-18 | D19: 2500AMP SSB-2 SUB BOARD REPLACE (EXPLOSION) | F19: TAMPOI | G19: CORPORAT | H19: GENERAL | M19: 1 | N19: UNIT | O19: 270333.96 | P19: 0 | Q19: 0 | R19: =SUM(O19:Q19) -> 270333.96 | S19: 120 | T19: -166705.75 | U19: -2252.78 | V19: =-$R19/$S19 -> -2252.783 | W19: =-$R19/$S19 -> -2252.783 | X19: =-$R19/$S19 -> -2252.783 | Y19: =-$R19/$S19 -> -2252.783 | Z19: =-$R19/$S19 -> -2252.783 | AA19: =-$R19/$S19 -> -2252.783 | AB19: =-$R19/$S19 -> -2252.783 | AC19: =-$R19/$S19 -> -2252.783 | AD19: 0 | AE19: 0 | AF19: 0 | AG19: =SUM(U19:AF19) -> -20275.044 | AH19: 0 | AI19: =T19+AG19+AH19 -> -186980.79 | AK19: =R19+AI19 -> 83353.169 | AL19: =O19+T19 -> 103628.21
A20: 44782 | C20: IR-22-A0100091 | D20: 2 SETS OF ALUMINIUM DOOR (3X7) FOR BLOCK A MAIN OFFICE | E20: FEI XIONG INTERIOR & RENOVATION | F20: TAMPOI | G20: HR | H20: GENERAL | I20: N/A | J20: PU46718 | K20: 0337 | M20: 2 | N20: SET | O20: 2150 | P20: 0 | Q20: 0 | R20: =SUM(O20:Q20) -> 2150 | S20: 120 | T20: -412.13 | U20: -17.92 | V20: =-$R20/$S20 -> -17.916667 | W20: =-$R20/$S20 -> -17.916667 | X20: =-$R20/$S20 -> -17.916667 | Y20: =-$R20/$S20 -> -17.916667 | Z20: =-$R20/$S20 -> -17.916667 | AA20: =-$R20/$S20 -> -17.916667 | AB20: =-$R20/$S20 -> -17.916667 | AC20: =-$R20/$S20 -> -17.916667 | AD20: 0 | AE20: 0 | AF20: 0 | AG20: =SUM(U20:AF20) -> -161.25333 | AH20: 0 | AI20: =T20+AG20+AH20 -> -573.38333 | AK20: =R20+AI20 -> 1576.6167 | AL20: =O20+T20 -> 1737.87
A21: 44782 | C21: IR-22-A0100092 | D21: KALPHA 6+8 SEATER CLUSTER WORKSTATION WITH 14 X SILVER ALLUMINIUM & WIRE FLIPPER CASINGS-RENOVATION WORK AT TAMPOI MAIN OFFICE BLOCK A | E21: KK OFFICEPOINT SDN BHD | F21: TAMPOI | G21: HR | H21: GENERAL | I21: N/A | J21: PU46721 | K21: IN2206-0051 | M21: 1 | N21: SET | O21: 5700 | P21: 0 | Q21: 0 | R21: =SUM(O21:Q21) -> 5700 | S21: 120 | T21: -1092.5 | U21: -47.5 | V21: =-$R21/$S21 -> -47.5 | W21: =-$R21/$S21 -> -47.5 | X21: =-$R21/$S21 -> -47.5 | Y21: =-$R21/$S21 -> -47.5 | Z21: =-$R21/$S21 -> -47.5 | AA21: =-$R21/$S21 -> -47.5 | AB21: =-$R21/$S21 -> -47.5 | AC21: =-$R21/$S21 -> -47.5 | AD21: 0 | AE21: 0 | AF21: 0 | AG21: =SUM(U21:AF21) -> -427.5 | AH21: 0 | AI21: =T21+AG21+AH21 -> -1520 | AK21: =R21+AI21 -> 4180 | AL21: =O21+T21 -> 4607.5
A22: 44942 | C22: IR-23-A0100098 | D22: PROVISION OF MATERIALS, LABOUR, EQUIPMENT AND CONSUMABLE TO FABRICATE AND INSTALL MACHINERY FOUNDATION | E22: F-I ENGINEERING SDN BHD | F22: TAMPOI | G22: MAINT | H22: GENERAL | I22: 2201578 | J22: DT 1172/ DT 1225 | K22: 6947/ 6992 | L22: Installation works | M22: 1 | N22: Unit | O22: 44070 | P22: 0 | Q22: 0 | R22: =SUM(O22:Q22) -> 44070 | S22: 120 | T22: -6610.5 | U22: -367.25 | V22: =-$R22/$S22 -> -367.25 | W22: =-$R22/$S22 -> -367.25 | X22: =-$R22/$S22 -> -367.25 | Y22: =-$R22/$S22 -> -367.25 | Z22: =-$R22/$S22 -> -367.25 | AA22: =-$R22/$S22 -> -367.25 | AB22: =-$R22/$S22 -> -367.25 | AC22: =-$R22/$S22 -> -367.25 | AD22: 0 | AE22: 0 | AF22: 0 | AG22: =SUM(U22:AF22) -> -3305.25 | AH22: 0 | AI22: =T22+AG22+AH22 -> -9915.75 | AK22: =R22+AI22 -> 34154.25 | AL22: =O22+T22 -> 37459.5
A23: 44965 | C23: IR-23-A0100100 | D23: MANIFOLD AND PIPING SYSTEM OF GC P-AIR MANIFOLD SYSTEM P-AIR PIPING SYSTEM NITROGEN MANIFOLD AND PIPING SYSTEM HYDROGEN MANIFOLD AND PIPING SYSTEM HELIUM MANIFOLD AND PIPING SYSTEM MANIFOLD AND PIPING SYSTEM OF OTR OXYGEN MANIFOLD AND PIPING SYSTEM 98% NITROGEN 2% HYDROGEN MANIFOLD AND PIPING SYSTEM MANIFOLD AND PIPING SYSTEM OF WVTR NITROGEN MANIFOLD AND PIPING SYSTEM | E23: PIALA ENGINEERING & SERVICES | F23: TAMPOI | G23: QC | H23: GENERAL | I23: 2300145 | J23: DT 1241/ DT 1227 | K23: INV000860/ INV000858 | L23: Installation works | M23: 1 | N23: Unit | O23: 51000 | P23: 0 | Q23: 0 | R23: =SUM(O23:Q23) -> 51000 | S23: 120 | T23: -7225 | U23: -425 | V23: =-$R23/$S23 -> -425 | W23: =-$R23/$S23 -> -425 | X23: =-$R23/$S23 -> -425 | Y23: =-$R23/$S23 -> -425 | Z23: =-$R23/$S23 -> -425 | AA23: =-$R23/$S23 -> -425 | AB23: =-$R23/$S23 -> -425 | AC23: =-$R23/$S23 -> -425 | AD23: 0 | AE23: 0 | AF23: 0 | AG23: =SUM(U23:AF23) -> -3825 | AH23: 0 | AI23: =T23+AG23+AH23 -> -11050 | AK23: =R23+AI23 -> 39950 | AL23: =O23+T23 -> 43775
A24: 44970 | C24: IR-23-A0100102 | D24: ADDITIONAL WORK OF MS STAIRCASE FOR BLOCK A TO SUPPLY & INSTALL ESCAPE LADDER FROM BLOCK A LABORATORY OFFICE TO GROUND FLOOR,USING METAL PLATFORM & STAIRCASE C/W PAINTING | E24: CBE M&E ENGINEERING SDN BHD | F24: TAMPOI | G24: MAINT | H24: GENERAL | I24: 2201898 | J24: 49394 | K24: INV2594 | L24: Installation works | M24: 1 | N24: lot | O24: 10625 | P24: 0 | Q24: 0 | R24: =SUM(O24:Q24) -> 10625 | S24: 120 | T24: -1505.195 | U24: -88.54 | V24: =-$R24/$S24 -> -88.541667 | W24: =-$R24/$S24 -> -88.541667 | X24: =-$R24/$S24 -> -88.541667 | Y24: =-$R24/$S24 -> -88.541667 | Z24: =-$R24/$S24 -> -88.541667 | AA24: =-$R24/$S24 -> -88.541667 | AB24: =-$R24/$S24 -> -88.541667 | AC24: =-$R24/$S24 -> -88.541667 | AD24: 0 | AE24: 0 | AF24: 0 | AG24: =SUM(U24:AF24) -> -796.87333 | AH24: 0 | AI24: =T24+AG24+AH24 -> -2302.0683 | AK24: =R24+AI24 -> 8322.9317 | AL24: =O24+T24 -> 9119.805
A25: 44970 | C25: IR-23-A0100101 | D25: ADDITIONAL RC PLINTH & STEEL PLATFORM FOR SMOKE SPILL SYSTEM EQUIPMENT | E25: CBE M&E ENGINEERING SDN BHD | F25: TAMPOI | G25: MAINT | H25: GENERAL | I25: 2300037 | J25: DT 1243 | K25: INV2593 | L25: Installation works | M25: 1 | N25: lot | O25: 75331 | P25: 0 | Q25: 0 | R25: =SUM(O25:Q25) -> 75331 | S25: 120 | T25: -10671.905 | U25: -627.76 | V25: =-$R25/$S25 -> -627.75833 | W25: =-$R25/$S25 -> -627.75833 | X25: =-$R25/$S25 -> -627.75833 | Y25: =-$R25/$S25 -> -627.75833 | Z25: =-$R25/$S25 -> -627.75833 | AA25: =-$R25/$S25 -> -627.75833 | AB25: =-$R25/$S25 -> -627.75833 | AC25: =-$R25/$S25 -> -627.75833 | AD25: 0 | AE25: 0 | AF25: 0 | AG25: =SUM(U25:AF25) -> -5649.8267 | AH25: 0 | AI25: =T25+AG25+AH25 -> -16321.732 | AK25: =R25+AI25 -> 59009.268 | AL25: =O25+T25 -> 64659.095
A26: 44782 | C26: IR-22-B0100092 | D26: KALPHA L-SHAPED TABLE WITH WOODEN DIVIDE PANEL & 1X SILVER ALUMINIUM WIRE FLIPPER CASING-RENOVATION WORK AT TAMPOI MAIN OFFICE BLOCK A | E26: KK OFFICEPOINT SDN BHD | F26: TAMPOI | G26: HR | H26: GENERAL | I26: N/A | J26: PU46721 | K26: IN2206-0051 | M26: 1 | N26: Unit | O26: 980 | P26: 0 | Q26: 0 | R26: =SUM(O26:Q26) -> 980 | S26: 60 | T26: -375.62 | U26: -16.33 | V26: =-$R26/$S26 -> -16.333333 | W26: =-$R26/$S26 -> -16.333333 | X26: =-$R26/$S26 -> -16.333333 | Y26: =-$R26/$S26 -> -16.333333 | Z26: =-$R26/$S26 -> -16.333333 | AA26: =-$R26/$S26 -> -16.333333 | AB26: =-$R26/$S26 -> -16.333333 | AC26: =-$R26/$S26 -> -16.333333 | AD26: 0 | AE26: 0 | AF26: 0 | AG26: =SUM(U26:AF26) -> -146.99667 | AH26: 0 | AI26: =T26+AG26+AH26 -> -522.61667 | AK26: =R26+AI26 -> 457.38333 | AL26: =O26+T26 -> 604.38
A27: 44782 | C27: IR-22-B0300092 | D27: WOODEN MOBILE PEDESTAL 3-DRAWER-RENOVATION WORK AT TAMPOI MAIN OFFICE BLOCK A | E27: KK OFFICEPOINT SDN BHD | F27: TAMPOI | G27: HR | H27: GENERAL | I27: N/A | J27: PU46721 | K27: IN2206-0051 | M27: 15 | N27: Unit | O27: 3120 | P27: 0 | Q27: 0 | R27: =SUM(O27:Q27) -> 3120 | S27: 120 | T27: -598 | U27: -26 | V27: =-$R27/$S27 -> -26 | W27: =-$R27/$S27 -> -26 | X27: =-$R27/$S27 -> -26 | Y27: =-$R27/$S27 -> -26 | Z27: =-$R27/$S27 -> -26 | AA27: =-$R27/$S27 -> -26 | AB27: =-$R27/$S27 -> -26 | AC27: =-$R27/$S27 -> -26 | AD27: 0 | AE27: 0 | AF27: 0 | AG27: =SUM(U27:AF27) -> -234 | AH27: 0 | AI27: =T27+AG27+AH27 -> -832 | AK27: =R27+AI27 -> 2288 | AL27: =O27+T27 -> 2522
A28: 44865 | C28: IR-22-A0100095 | D28: KALPHA 6 SEATER CLUSTER WORKSTATION WITH 3 X WOODEN PANEL + 6X SILVER WIRE FLIPPER CASINGS | E28: KK OFFICEPOINT SDN BHD | F28: TAMPOI | G28: HR | H28: GENERAL | I28: N/A | J28: PU47690 | K28: IN2209-0757 | M28: 1 | N28: SET | O28: 2450 | P28: 0 | Q28: 0 | R28: =SUM(O28:Q28) -> 2450 | S28: 120 | T28: -428.79 | U28: -20.42 | V28: =-$R28/$S28 -> -20.416667 | W28: =-$R28/$S28 -> -20.416667 | X28: =-$R28/$S28 -> -20.416667 | Y28: =-$R28/$S28 -> -20.416667 | Z28: =-$R28/$S28 -> -20.416667 | AA28: =-$R28/$S28 -> -20.416667 | AB28: =-$R28/$S28 -> -20.416667 | AC28: =-$R28/$S28 -> -20.416667 | AD28: 0 | AE28: 0 | AF28: 0 | AG28: =SUM(U28:AF28) -> -183.75333 | AH28: 0 | AI28: =T28+AG28+AH28 -> -612.54333 | AK28: =R28+AI28 -> 1837.4567 | AL28: =O28+T28 -> 2021.21
A29: 45002 | C29: IR-23-A0100105 | D29: PRINTING OFFICE LABOUR SUPPLY AND TOOLS TO DISMANTLE EXISTING CEILING,TABLE & PARTITION C/W SITE CLEANING PRINTING OFFICE 2' X 4' X 9MM THK LAMINATED CEILING BOARD & FRAME ONE LAYER 12MM THK PLASTERING PARTITION TWO LAYER 12MM THK PLASTERING PARTITION 3' X 7' ALUMINIUM DOOR C/W DOOR FRAME WALL PAINTING WORKS | E29: F-I ENGINEERING SDN BHD | F29: TAMPOI | G29: MAINT | H29: GENERAL | I29: 2300274 | J29: 49111 | K29: 7028 | L29: Installation works | M29: 1 | N29: Unit | O29: 11526.92 | P29: 0 | Q29: 0 | R29: =SUM(O29:Q29) -> 11526.92 | S29: 120 | T29: -1536.939 | U29: -96.06 | V29: =-$R29/$S29 -> -96.057667 | W29: =-$R29/$S29 -> -96.057667 | X29: =-$R29/$S29 -> -96.057667 | Y29: =-$R29/$S29 -> -96.057667 | Z29: =-$R29/$S29 -> -96.057667 | AA29: =-$R29/$S29 -> -96.057667 | AB29: =-$R29/$S29 -> -96.057667 | AC29: =-$R29/$S29 -> -96.057667 | AD29: 0 | AE29: 0 | AF29: 0 | AG29: =SUM(U29:AF29) -> -864.52133 | AH29: 0 | AI29: =T29+AG29+AH29 -> -2401.4603 | AK29: =R29+AI29 -> 9125.4597 | AL29: =O29+T29 -> 9989.981
A30: 45063 | C30: IR-23-A0100107 | D30: SUPPLY & LAY ADDITIONAL UV COATING ON SURFACE | E30: CBE M&E ENGINEERING SDN BHD | F30: TAMPOI | G30: MAINT | H30: GENERAL | I30: 2300771 | J30: DT1303/ DT1304/ DT1305 | K30: INV2632/ INV2632-A/ INV2632-B | L30: Installation works | M30: 1 | N30: lot | O30: 283300 | P30: 0 | Q30: 0 | R30: =SUM(O30:Q30) -> 283300 | S30: 120 | T30: -33051.65 | U30: -2360.83 | V30: =-$R30/$S30 -> -2360.8333 | W30: =-$R30/$S30 -> -2360.8333 | X30: =-$R30/$S30 -> -2360.8333 | Y30: =-$R30/$S30 -> -2360.8333 | Z30: =-$R30/$S30 -> -2360.8333 | AA30: =-$R30/$S30 -> -2360.8333 | AB30: =-$R30/$S30 -> -2360.8333 | AC30: =-$R30/$S30 -> -2360.8333 | AD30: 0 | AE30: 0 | AF30: 0 | AG30: =SUM(U30:AF30) -> -21247.497 | AH30: 0 | AI30: =T30+AG30+AH30 -> -54299.147 | AK30: =R30+AI30 -> 229000.85 | AL30: =O30+T30 -> 250248.35
A31: 44865 | C31: IR-22-B0100095 | D31: MOBILE PEDESTAL 2-DRAWER 1 FILING | E31: KK OFFICEPOINT SDN BHD | F31: TAMPOI | G31: HR | H31: GENERAL | I31: N/A | J31: PU47690 | K31: IN2209-0757 | M31: 6 | N31: Unit | O31: 1248 | P31: 0 | Q31: 0 | R31: =SUM(O31:Q31) -> 1248 | S31: 120 | T31: -218.4 | U31: -10.4 | V31: =-$R31/$S31 -> -10.4 | W31: =-$R31/$S31 -> -10.4 | X31: =-$R31/$S31 -> -10.4 | Y31: =-$R31/$S31 -> -10.4 | Z31: =-$R31/$S31 -> -10.4 | AA31: =-$R31/$S31 -> -10.4 | AB31: =-$R31/$S31 -> -10.4 | AC31: =-$R31/$S31 -> -10.4 | AD31: 0 | AE31: 0 | AF31: 0 | AG31: =SUM(U31:AF31) -> -93.6 | AH31: 0 | AI31: =T31+AG31+AH31 -> -312 | AK31: =R31+AI31 -> 936 | AL31: =O31+T31 -> 1029.6
A32: 44935 | C32: IR-23-A0100096 | D32: TAMPOI BLOCK A PT 8C RIGHT TO LEFT TO SUPPLY LABOUR AND MATERIAL TO INSTALL EXHAUST DUCTING TO ROOFTOP 3M C/W ROOFING (INCLUDE INVERTER CAP,NUMBERING AND SAMPLING PORT) TO SUPPLY LABOUR MATERIAL TO INSTALL BURNER DUCTING AND JOINT TO MACHINE C/W 100MM FIBERGLASS EXTERNAL INSULATION TO SUPPLY LABOUR AND MATERIAL TO INSTALL SOLVENT EXHAUST DUCTING TO ROOFTOP 3M C/W ROOFING(INCLUDE INVERTER CAP,NUMBERING AND SAMPLING PORT) TO SUPPLY LABOUR AND MATERIAL TO INSTALL 2NOS EXHAUST BLOWER (NO INCLUDE WIRING WORK) TO SUPPLY LABOUR AND MATERIAL TO INSTALL FILTER BOX C/W PRESSURE GAUGE METER(INCLUDE CARBON FILTER) | E32: BAN KIM ENGINEERING WORKS | F32: TAMPOI | G32: MAINT | H32: GENERAL | I32: 2200956 | J32: PU48411 | K32: 23/01-008 | L32: Installation works | M32: 1 | N32: Unit | O32: 103000 | P32: 0 | Q32: 0 | R32: =SUM(O32:Q32) -> 103000 | S32: 120 | T32: -15449.97 | U32: -858.33 | V32: =-$R32/$S32 -> -858.33333 | W32: =-$R32/$S32 -> -858.33333 | X32: =-$R32/$S32 -> -858.33333 | Y32: =-$R32/$S32 -> -858.33333 | Z32: =-$R32/$S32 -> -858.33333 | AA32: =-$R32/$S32 -> -858.33333 | AB32: =-$R32/$S32 -> -858.33333 | AC32: =-$R32/$S32 -> -858.33333 | AD32: 0 | AE32: 0 | AF32: 0 | AG32: =SUM(U32:AF32) -> -7724.9967 | AH32: 0 | AI32: =T32+AG32+AH32 -> -23174.967 | AK32: =R32+AI32 -> 79825.033 | AL32: =O32+T32 -> 87550.03
A33: 44939 | C33: IR-23-A0100097 | D33: TAMPOI BLOCK A PT 9C TO SUPPLY LABOUR AND MATERIAL TO INSTALL EXHAUST DUCTING TO ROOFTOP 3M C/W ROOFING (INCLUDE INVERTER CAP,NUMBERING AND SAMPLING PORT) TO SUPPLY LABOUR MATERIAL TO INSTALL BURNER DUCTING AND JOINT TO MACHINE C/W 100MM FIBERGLASS EXTERNAL INSULATION TO SUPPLY LABOUR AND MATERIAL TO INSTALL SOLVENT EXHAUST DUCTING TO ROOFTOP 3M C/W ROOFING(INCLUDE INVERTER CAP,NUMBERING AND SAMPLING PORT) TO SUPPLY LABOUR AND MATERIAL TO INSTALL 2NOS EXHAUST BLOWER (NO INCLUDE WIRING WORK) TO SUPPLY LABOUR AND MATERIAL TO INSTALL FILTER BOX C/W PRESSURE GAUGE METER(INCLUDE CARBON FILTER) | E33: BAN KIM ENGINEERING WORKS | F33: TAMPOI | G33: MAINT | H33: GENERAL | I33: 2200954 | J33: PU48668 | K33: 23/01-020 | L33: Installation works | M33: 1 | N33: Unit | O33: 105000 | P33: 0 | Q33: 0 | R33: =SUM(O33:Q33) -> 105000 | S33: 120 | T33: -15750 | U33: -875 | V33: =-$R33/$S33 -> -875 | W33: =-$R33/$S33 -> -875 | X33: =-$R33/$S33 -> -875 | Y33: =-$R33/$S33 -> -875 | Z33: =-$R33/$S33 -> -875 | AA33: =-$R33/$S33 -> -875 | AB33: =-$R33/$S33 -> -875 | AC33: =-$R33/$S33 -> -875 | AD33: 0 | AE33: 0 | AF33: 0 | AG33: =SUM(U33:AF33) -> -7875 | AH33: 0 | AI33: =T33+AG33+AH33 -> -23625 | AK33: =R33+AI33 -> 81375 | AL33: =O33+T33 -> 89250
A34: 45078 | C34: IR-23-A0100111 | D34: ADDITIONAL CEILING WORK BLOCK A & C TO SUPPLY & INSTALL 9MM GYPSUM CEILING FOR AREA | E34: CBE M&E ENGINEERING SDN BHD | F34: TAMPOI | G34: MAINT | H34: GENERAL | I34: 2300869 | J34: PU50340 | K34: INV2640 | L34: Installation works | M34: 1 | N34: Unit | O34: 7000 | P34: 0 | Q34: 0 | R34: =SUM(O34:Q34) -> 7000 | S34: 120 | T34: -758.32 | U34: -58.33 | V34: =-$R34/$S34 -> -58.333333 | W34: =-$R34/$S34 -> -58.333333 | X34: =-$R34/$S34 -> -58.333333 | Y34: =-$R34/$S34 -> -58.333333 | Z34: =-$R34/$S34 -> -58.333333 | AA34: =-$R34/$S34 -> -58.333333 | AB34: =-$R34/$S34 -> -58.333333 | AC34: =-$R34/$S34 -> -58.333333 | AD34: 0 | AE34: 0 | AF34: 0 | AG34: =SUM(U34:AF34) -> -524.99667 | AH34: 0 | AI34: =T34+AG34+AH34 -> -1283.3167 | AK34: =R34+AI34 -> 5716.6833 | AL34: =O34+T34 -> 6241.68
A35: 45084 | C35: IR-23-A0100112 | D35: ADDITIONAL DOOR & WINDOW AT BASEMENT BLOCK C SUPPLY & INSTALL ALUMINIUM WINDOW C/W 4.5MM | E35: CBE M&E ENGINEERING SDN BHD | F35: TAMPOI | G35: MAINT | H35: GENERAL | I35: 2300922 | J35: PU50342 | K35: INV2645 | L35: Installation works | M35: 1 | N35: Unit | O35: 7200 | P35: 0 | Q35: 0 | R35: =SUM(O35:Q35) -> 7200 | S35: 120 | T35: -780 | U35: -60 | V35: =-$R35/$S35 -> -60 | W35: =-$R35/$S35 -> -60 | X35: =-$R35/$S35 -> -60 | Y35: =-$R35/$S35 -> -60 | Z35: =-$R35/$S35 -> -60 | AA35: =-$R35/$S35 -> -60 | AB35: =-$R35/$S35 -> -60 | AC35: =-$R35/$S35 -> -60 | AD35: 0 | AE35: 0 | AF35: 0 | AG35: =SUM(U35:AF35) -> -540 | AH35: 0 | AI35: =T35+AG35+AH35 -> -1320 | AK35: =R35+AI35 -> 5880 | AL35: =O35+T35 -> 6420
A36: 44958 | C36: IR-23-A0100099 | D36: TO SUPPLY & INSTALL S/S304 2B EXHAUST VENTILATION SYSTEM FOR SUPER COMBI & DUPLEX COMBI LINEAR TANDE | E36: GUAN SHENG ENGINEERING SDN BHD | F36: TAMPOI | G36: MAINT | H36: GENERAL | I36: 2201330 | J36: DT1124/ DT1175/ DT1191/ DT1254/ DT1264/ DT1267 | K36: INV002675/ INV002689/ INV002688/ INV002796/ INV002835/ INV002834 | M36: 1 | N36: Unit | O36: 580888 | P36: 0 | Q36: 0 | R36: =SUM(O36:Q36) -> 580888 | S36: 120 | T36: -82292.44 | U36: -4840.73 | V36: =-$R36/$S36 -> -4840.7333 | W36: =-$R36/$S36 -> -4840.7333 | X36: =-$R36/$S36 -> -4840.7333 | Y36: =-$R36/$S36 -> -4840.7333 | Z36: =-$R36/$S36 -> -4840.7333 | AA36: =-$R36/$S36 -> -4840.7333 | AB36: =-$R36/$S36 -> -4840.7333 | AC36: =-$R36/$S36 -> -4840.7333 | AD36: 0 | AE36: 0 | AF36: 0 | AG36: =SUM(U36:AF36) -> -43566.597 | AH36: 0 | AI36: =T36+AG36+AH36 -> -125859.04 | AK36: =R36+AI36 -> 455028.96 | AL36: =O36+T36 -> 498595.56
A37: 45131 | C37: IR-23-A0100115 | D37: BLOCK B (CYLINDER ROOM) SURFACE PREPARATION TO GRIND THE FLOOR TO PREPARE SUBSTRATE TO RECEIVE NEW FLOOR FINISHES FLOORING AT CYLINDER ROOM & CYLINDER STORE ROOMFLOOR FINISHES SUPPLY & APPLY BC CRETE MF UV (2MM) SELF SMOOTHING THERMAL SHOCK POLYURETHANE FLOOR FINISHES SUPPLY & APPLY BC DECK UV (2COATS) A UV STABLE 2 COMPONENTS COATING BASED ON HIGH QUALITY POLYESTER BRANCHED POLYURETHANE RESIN BLOCK B (CYLINDER ROOM) SURFACE PREPARATION TO GRIND THE FLOOR TO PREPARE SUBSTRATE TO RECEIVE NEW FLOOR FINISHES FLOOR FINISHES SUPPLY & APPLY BC CRETE MF UV (2MM) SELF SMOOTHING THERMAL SHOCK POLYURETHANE FLOOR FINISHES | E37: CBE M&E ENGINEERING SDN BHD | F37: TAMPOI | G37: MAINT | H37: GENERAL | I37: 2301152 | J37: PU50745 | K37: INV2664 | L37: Installation works | M37: 1 | N37: Unit | O37: 68260 | P37: 0 | Q37: 0 | R37: =SUM(O37:Q37) -> 68260 | S37: 120 | T37: -6825.99 | U37: -568.83 | V37: =-$R37/$S37 -> -568.83333 | W37: =-$R37/$S37 -> -568.83333 | X37: =-$R37/$S37 -> -568.83333 | Y37: =-$R37/$S37 -> -568.83333 | Z37: =-$R37/$S37 -> -568.83333 | AA37: =-$R37/$S37 -> -568.83333 | AB37: =-$R37/$S37 -> -568.83333 | AC37: =-$R37/$S37 -> -568.83333 | AD37: 0 | AE37: 0 | AF37: 0 | AG37: =SUM(U37:AF37) -> -5119.4967 | AH37: 0 | AI37: =T37+AG37+AH37 -> -11945.487 | AK37: =R37+AI37 -> 56314.513 | AL37: =O37+T37 -> 61434.01
A38: 44974 | C38: IR-23-A0100103 | D38: 3MM THK 304 S/STEEL PLATE C/W CUT,BEND & WELDING (PRINTING LINE 1 (6 COLOR)) | E38: F-I ENGINEERING SDN BHD | F38: TAMPOI | G38: MAINT | H38: GENERAL | I38: 2201815 | J38: DT1284/ DT1283 | K38: 6970/ 7011 | M38: 1 | N38: Unit | O38: 58520 | P38: 0 | Q38: 0 | R38: =SUM(O38:Q38) -> 58520 | S38: 120 | T38: -8290.36 | U38: -487.67 | V38: =-$R38/$S38 -> -487.66667 | W38: =-$R38/$S38 -> -487.66667 | X38: =-$R38/$S38 -> -487.66667 | Y38: =-$R38/$S38 -> -487.66667 | Z38: =-$R38/$S38 -> -487.66667 | AA38: =-$R38/$S38 -> -487.66667 | AB38: =-$R38/$S38 -> -487.66667 | AC38: =-$R38/$S38 -> -487.66667 | AD38: 0 | AE38: 0 | AF38: 0 | AG38: =SUM(U38:AF38) -> -4389.0033 | AH38: 0 | AI38: =T38+AG38+AH38 -> -12679.363 | AK38: =R38+AI38 -> 45840.637 | AL38: =O38+T38 -> 50229.64
A39: 45124 | C39: IR-23-A0100114 | D39: LAMINATION OFFICE LABOUR SUPPLY AND TOOLS TO DISMANTLE EXISTING CEILING,TABLE & PARTITION C/W SITE CLEANING TWO LAYER 12MM THK PLASTERING PARTITION | E39: F-I ENGINEERING SDN BHD | F39: TAMPOI | G39: MAINT | H39: General | I39: 2300307 | J39: PU50466 | K39: 7096 | L39: Installation works | M39: 1 | N39: Unit | O39: 17000 | P39: 0 | Q39: 0 | R39: =SUM(O39:Q39) -> 17000 | S39: 120 | T39: -1700 | U39: =-$R39/$S39 -> -141.66667 | V39: =-$R39/$S39 -> -141.66667 | W39: =-$R39/$S39 -> -141.66667 | X39: =-$R39/$S39 -> -141.66667 | Y39: =-$R39/$S39 -> -141.66667 | Z39: =-$R39/$S39 -> -141.66667 | AA39: =-$R39/$S39 -> -141.66667 | AB39: =-$R39/$S39 -> -141.66667 | AC39: =-$R39/$S39 -> -141.66667 | AD39: 0 | AE39: 0 | AF39: 0 | AG39: =SUM(U39:AF39) -> -1275 | AH39: 0 | AI39: =T39+AG39+AH39 -> -2975 | AK39: =R39+AI39 -> 14025 | AL39: =O39+T39 -> 15300
A40: 44974 | C40: IR-23-A0100104 | D40: 3MM 304 S/STEEL PLATE C/W CUT & WELDING (PRINTING LINE 2 (8 COLOR)) | E40: F-I ENGINEERING SDN BHD | F40: TAMPOI | G40: MAINT | H40: GENERAL | I40: 2201813 | J40: PU48827 | K40: 6971/ 700 | M40: 1 | N40: Unit | O40: 58520 | P40: 0 | Q40: 0 | R40: =SUM(O40:Q40) -> 58520 | S40: 120 | T40: -8290.36 | U40: -487.67 | V40: =-$R40/$S40 -> -487.66667 | W40: =-$R40/$S40 -> -487.66667 | X40: =-$R40/$S40 -> -487.66667 | Y40: =-$R40/$S40 -> -487.66667 | Z40: =-$R40/$S40 -> -487.66667 | AA40: =-$R40/$S40 -> -487.66667 | AB40: =-$R40/$S40 -> -487.66667 | AC40: =-$R40/$S40 -> -487.66667 | AD40: 0 | AE40: 0 | AF40: 0 | AG40: =SUM(U40:AF40) -> -4389.0033 | AH40: 0 | AI40: =T40+AG40+AH40 -> -12679.363 | AK40: =R40+AI40 -> 45840.637 | AL40: =O40+T40 -> 50229.64
...

Sheet PM
A1: =[33]LAND!A1 -> TOMYPAK FLEXIBLE PACKAGING SDN BHD
A2: =[33]LAND!A2 -> FOR THE YEAR ENDED 30 JUNE 2025 | G2: BASED ON SAP
A3: PLANT AND MACHINERIES | G3: NOT YET PAY/ NOT FULLY PAY
A4: 11101-018 | G4: PV NOT SIGNED | AL4: Closing | AM4: Opening
A5: Acquisition Date | B5: Disposal Date | C5: F/A Code | D5: F/A Description | E5: Suppliers | F5: Cost Ctr. 1 | G5: Cost Ctr. 2 | H5: Cost Ctr. 3 | I5: Purchase Order | J5: NO. | K5: Invoice No. | L5: Remarks | M5: Original Currency | N5: Quantity | O5: UOM | P5: Cost c/f | Q5: Addition | R5: Disposal/ Written off | S5: Cost b/f | T5: Months | U5: Acc Depn b/f | V5: Jul | W5: Aug | X5: Sept | Y5: Oct | Z5: Nov | AA5: Dec | AB5: Jan | AC5: Feb | AD5: Mar | AE5: Apr | AF5: May | AG5: Jun | AH5: Current Year Depn | AI5: Disposal/ Written off | AJ5: Acc Depn c/f | AL5: =FBT!AA5 -> NBV As At 30/06/2025 | AM5: =FBT!AB5 -> NBV As At 30/06/2024
A6: 40755 | C6: PM00-0012/9 | D6: RATING: 15KW | F6: TAMPOI | G6: PROD | H6: General | L6: Installation | N6: 1 | O6: Unit | P6: 10000 | Q6: 0 | R6: 0 | S6: =SUM(P6:R6) -> 10000 | T6: 120 | U6: -10000 | V6: 0 | W6: 0 | X6: 0 | Y6: 0 | Z6: 0 | AA6: 0 | AB6: 0 | AC6: 0 | AD6: 0 | AE6: 0 | AF6: 0 | AG6: 0 | AH6: =SUM(V6:AG6) -> 0 | AI6: 0 | AJ6: =U6+AH6+AI6 -> -10000 | AL6: =S6+AJ6 -> 0 | AM6: =P6+U6 -> 0
A7: 40755 | C7: PM00-0053/33 | D7: 1200MM L - TO DO GRINDING ON IMPRESS R/R NO.1 SCHIAVI | F7: TAMPOI | G7: PROD | H7: General | N7: 1 | O7: Unit | P7: 470 | Q7: 0 | R7: 0 | S7: =SUM(P7:R7) -> 470 | T7: 120 | U7: -470 | V7: 0 | W7: 0 | X7: 0 | Y7: 0 | Z7: 0 | AA7: 0 | AB7: 0 | AC7: 0 | AD7: 0 | AE7: 0 | AF7: 0 | AG7: 0 | AH7: =SUM(V7:AG7) -> 0 | AI7: 0 | AJ7: =U7+AH7+AI7 -> -470 | AL7: =S7+AJ7 -> 0 | AM7: =P7+U7 -> 0
A8: 40755 | C8: PM00-0062/36 | D8: TYPE: UGCMED - 37AA406 FOR D/L,PT 1 &2 & E/L | F8: TAMPOI | G8: PROD | H8: General | N8: 1 | O8: Unit | P8: 10073.7 | Q8: 0 | R8: 0 | S8: =SUM(P8:R8) -> 10073.7 | T8: 120 | U8: -10073.7 | V8: 0 | W8: 0 | X8: 0 | Y8: 0 | Z8: 0 | AA8: 0 | AB8: 0 | AC8: 0 | AD8: 0 | AE8: 0 | AF8: 0 | AG8: 0 | AH8: =SUM(V8:AG8) -> 0 | AI8: 0 | AJ8: =U8+AH8+AI8 -> -10073.7 | AL8: =S8+AJ8 -> 0 | AM8: =P8+U8 -> 0
A9: 40755 | C9: PM00-0064/36 | D9: TYPE: UGCMED - 04AA206 FOR D/L,PT 1 &2 & E/L | F9: TAMPOI | G9: PROD | H9: General | N9: 1 | O9: Unit | P9: 4141.8 | Q9: 0 | R9: 0 | S9: =SUM(P9:R9) -> 4141.8 | T9: 120 | U9: -4141.8 | V9: 0 | W9: 0 | X9: 0 | Y9: 0 | Z9: 0 | AA9: 0 | AB9: 0 | AC9: 0 | AD9: 0 | AE9: 0 | AF9: 0 | AG9: 0 | AH9: =SUM(V9:AG9) -> 0 | AI9: 0 | AJ9: =U9+AH9+AI9 -> -4141.8 | AL9: =S9+AJ9 -> 0 | AM9: =P9+U9 -> 0
A10: 40755 | C10: PM00-0065/36 | D10: @JPY103000/PC LESS DIS. JPY3K ZA-5A 24V DC FOR EL, DL & SL | F10: TAMPOI | G10: PROD | H10: General | N10: 1 | O10: Unit | P10: 7020 | Q10: 0 | R10: 0 | S10: =SUM(P10:R10) -> 7020 | T10: 120 | U10: -7020 | V10: 0 | W10: 0 | X10: 0 | Y10: 0 | Z10: 0 | AA10: 0 | AB10: 0 | AC10: 0 | AD10: 0 | AE10: 0 | AF10: 0 | AG10: 0 | AH10: =SUM(V10:AG10) -> 0 | AI10: 0 | AJ10: =U10+AH10+AI10 -> -7020 | AL10: =S10+AJ10 -> 0 | AM10: =P10+U10 -> 0
A11: 40755 | C11: PM00-0088/49 | D11: COMPRESSOR KST 22.4 FOR FOR NO. 1 & 4 AIR COMPRESSOR | F11: TAMPOI | G11: PROD | H11: General | N11: 1 | O11: Unit | P11: 8738 | Q11: 0 | R11: 0 | S11: =SUM(P11:R11) -> 8738 | T11: 120 | U11: -8738 | V11: 0 | W11: 0 | X11: 0 | Y11: 0 | Z11: 0 | AA11: 0 | AB11: 0 | AC11: 0 | AD11: 0 | AE11: 0 | AF11: 0 | AG11: 0 | AH11: =SUM(V11:AG11) -> 0 | AI11: 0 | AJ11: =U11+AH11+AI11 -> -8738 | AL11: =S11+AJ11 -> 0 | AM11: =P11+U11 -> 0
A12: 40755 | C12: PM00-0172/111 | D12: 1 UNIT CHILLER TANK C/W INSULA INSULATION & BUFFLE PLATE,PIP' 4 NO | F12: TAMPOI | G12: CPP | H12: General | N12: 1 | O12: Unit | P12: 24800 | Q12: 0 | R12: 0 | S12: =SUM(P12:R12) -> 24800 | T12: 120 | U12: -24800 | V12: 0 | W12: 0 | X12: 0 | Y12: 0 | Z12: 0 | AA12: 0 | AB12: 0 | AC12: 0 | AD12: 0 | AE12: 0 | AF12: 0 | AG12: 0 | AH12: =SUM(V12:AG12) -> 0 | AI12: 0 | AJ12: =U12+AH12+AI12 -> -24800 | AL12: =S12+AJ12 -> 0 | AM12: =P12+U12 -> 0
A13: 40755 | C13: PM00-0173/112 | D13: FLOW CAPACITY: 636 CFM @ RM4000/UNIT | F13: TAMPOI | G13: PROD | H13: General | N13: 1 | O13: Unit | P13: 8000 | Q13: 0 | R13: 0 | S13: =SUM(P13:R13) -> 8000 | T13: 120 | U13: -8000 | V13: 0 | W13: 0 | X13: 0 | Y13: 0 | Z13: 0 | AA13: 0 | AB13: 0 | AC13: 0 | AD13: 0 | AE13: 0 | AF13: 0 | AG13: 0 | AH13: =SUM(V13:AG13) -> 0 | AI13: 0 | AJ13: =U13+AH13+AI13 -> -8000 | AL13: =S13+AJ13 -> 0 | AM13: =P13+U13 -> 0
A14: 40755 | C14: PM00-0179/116 | D14: TO WELD & MACHINE ROLLER | F14: TAMPOI | G14: PROD | H14: General | N14: 1 | O14: Unit | P14: 200 | Q14: 0 | R14: 0 | S14: =SUM(P14:R14) -> 200 | T14: 120 | U14: -200 | V14: 0 | W14: 0 | X14: 0 | Y14: 0 | Z14: 0 | AA14: 0 | AB14: 0 | AC14: 0 | AD14: 0 | AE14: 0 | AF14: 0 | AG14: 0 | AH14: =SUM(V14:AG14) -> 0 | AI14: 0 | AJ14: =U14+AH14+AI14 -> -200 | AL14: =S14+AJ14 -> 0 | AM14: =P14+U14 -> 0
A15: 40755 | C15: PM00-0183/120 | D15: FLOW CAPACITY: 424CFM INTER TEMPERATURE: 35 DEG C AMBI | F15: TAMPOI | G15: PROD | H15: General | N15: 1 | O15: Unit | P15: 11200 | Q15: 0 | R15: 0 | S15: =SUM(P15:R15) -> 11200 | T15: 120 | U15: -11200 | V15: 0 | W15: 0 | X15: 0 | Y15: 0 | Z15: 0 | AA15: 0 | AB15: 0 | AC15: 0 | AD15: 0 | AE15: 0 | AF15: 0 | AG15: 0 | AH15: =SUM(V15:AG15) -> 0 | AI15: 0 | AJ15: =U15+AH15+AI15 -> -11200 | AL15: =S15+AJ15 -> 0 | AM15: =P15+U15 -> 0
A16: 40755 | C16: PM00-0202/129 | D16: * 1320MM L - TO DO GRINDING -MATTRING RUBBER ROLLER | F16: TAMPOI | G16: PROD | H16: General | N16: 1 | O16: Unit | P16: 380 | Q16: 0 | R16: 0 | S16: =SUM(P16:R16) -> 380 | T16: 120 | U16: -380 | V16: 0 | W16: 0 | X16: 0 | Y16: 0 | Z16: 0 | AA16: 0 | AB16: 0 | AC16: 0 | AD16: 0 | AE16: 0 | AF16: 0 | AG16: 0 | AH16: =SUM(V16:AG16) -> 0 | AI16: 0 | AJ16: =U16+AH16+AI16 -> -380 | AL16: =S16+AJ16 -> 0 | AM16: =P16+U16 -> 0
A17: 40755 | C17: PM00-0218/136 | D17: RUG JPY60000 & 75 PCS RUG JPY60000 FOR STM - TOSHIN 5,6 & 7 | F17: TAMPOI | G17: PROD | H17: General | N17: 1 | O17: Unit | P17: 4968 | Q17: 0 | R17: 0 | S17: =SUM(P17:R17) -> 4968 | T17: 120 | U17: -4968 | V17: 0 | W17: 0 | X17: 0 | Y17: 0 | Z17: 0 | AA17: 0 | AB17: 0 | AC17: 0 | AD17: 0 | AE17: 0 | AF17: 0 | AG17: 0 | AH17: =SUM(V17:AG17) -> 0 | AI17: 0 | AJ17: =U17+AH17+AI17 -> -4968 | AL17: =S17+AJ17 -> 0 | AM17: =P17+U17 -> 0
A18: 40755 | C18: PM00-0228/145 | D18: 2PC RM100 & 1 PC 203 OD *150ID *100MM HOLLOW PIPE RM68 -MAI | F18: TAMPOI | G18: PROD | H18: General | L18: Installation | N18: 1 | O18: Unit | P18: 168 | Q18: 0 | R18: 0 | S18: =SUM(P18:R18) -> 168 | T18: 120 | U18: -168 | V18: 0 | W18: 0 | X18: 0 | Y18: 0 | Z18: 0 | AA18: 0 | AB18: 0 | AC18: 0 | AD18: 0 | AE18: 0 | AF18: 0 | AG18: 0 | AH18: =SUM(V18:AG18) -> 0 | AI18: 0 | AJ18: =U18+AH18+AI18 -> -168 | AL18: =S18+AJ18 -> 0 | AM18: =P18+U18 -> 0
A19: 40755 | C19: PM00-0240/153 | D19: TYPE UGCMED-04AA206 - MAINTENANCE | F19: TAMPOI | G19: PROD | H19: General | N19: 1 | O19: Unit | P19: 4953.28 | Q19: 0 | R19: 0 | S19: =SUM(P19:R19) -> 4953.28 | T19: 120 | U19: -4953.28 | V19: 0 | W19: 0 | X19: 0 | Y19: 0 | Z19: 0 | AA19: 0 | AB19: 0 | AC19: 0 | AD19: 0 | AE19: 0 | AF19: 0 | AG19: 0 | AH19: =SUM(V19:AG19) -> 0 | AI19: 0 | AJ19: =U19+AH19+AI19 -> -4953.28 | AL19: =S19+AJ19 -> 0 | AM19: =P19+U19 -> 0
A20: 40755 | C20: PM00-0247/159 | D20: & MACHINE HEAD OF EXTRUDER FOR RESIN FILTER FOR CPP | F20: TAMPOI | G20: CPP | H20: General | N20: 1 | O20: Unit | P20: 3200 | Q20: 0 | R20: 0 | S20: =SUM(P20:R20) -> 3200 | T20: 120 | U20: -3200 | V20: 0 | W20: 0 | X20: 0 | Y20: 0 | Z20: 0 | AA20: 0 | AB20: 0 | AC20: 0 | AD20: 0 | AE20: 0 | AF20: 0 | AG20: 0 | AH20: =SUM(V20:AG20) -> 0 | AI20: 0 | AJ20: =U20+AH20+AI20 -> -3200 | AL20: =S20+AJ20 -> 0 | AM20: =P20+U20 -> 0
A21: 41090 | C21: PM-00024A01-12 | D21: 4 SIDE SEAL BAG MAKING MACHINE | F21: TAMPOI | G21: BAGMAKE | H21: General | N21: 1 | O21: Unit | P21: 184207.96 | Q21: 0 | R21: 0 | S21: =SUM(P21:R21) -> 184207.96 | T21: 58 | U21: -184207.96 | V21: 0 | W21: 0 | X21: 0 | Y21: 0 | Z21: 0 | AA21: 0 | AB21: 0 | AC21: 0 | AD21: 0 | AE21: 0 | AF21: 0 | AG21: 0 | AH21: =SUM(V21:AG21) -> 0 | AI21: 0 | AJ21: =U21+AH21+AI21 -> -184207.96 | AL21: =S21+AJ21 -> 0 | AM21: =P21+U21 -> 0
A22: 41090 | C22: PM-00024A01-12/A | D22: 5 SIDE SEAL BAG MAKING MACHINE | F22: TAMPOI | G22: BAGMAKE | H22: General | N22: 1 | O22: Unit | P22: 200083.61 | Q22: 0 | R22: 0 | S22: =SUM(P22:R22) -> 200083.61 | T22: 62 | U22: -200083.61 | V22: 0 | W22: 0 | X22: 0 | Y22: 0 | Z22: 0 | AA22: 0 | AB22: 0 | AC22: 0 | AD22: 0 | AE22: 0 | AF22: 0 | AG22: 0 | AH22: =SUM(V22:AG22) -> 0 | AI22: 0 | AJ22: =U22+AH22+AI22 -> -200083.61 | AL22: =S22+AJ22 -> 0 | AM22: =P22+U22 -> 0
